Workbook

Sheet Overview
A1: Category | B1: Details
A2: Document Name | B2: EMI Manual Test Cases — B2B — By Feature
A3: Epic / Story Ref | B3: Full EMI manual suite: project docs + this audit + AIO (Jira)
A4: Release Number | B4: All releases to V 6.6.0 / Sprint 74
A5: Environment | B5: DEV
A6: Testing Period | B6: Sprint Test Execution Cycle
A9: EMI Manual Test Cases — B2B — Results by Feature
A11: Feature | B11: Passed | C11: Failed | D11: Partially Passed | E11: Not Tested | F11: Not Implemented | G11: Total Checks | H11: Pass Rate %
A12: Other | B12: =COUNTIF('Other'!$I:$I,"Passed") | C12: =COUNTIF('Other'!$I:$I,"Failed") | D12: =COUNTIF('Other'!$I:$I,"Partially Passed") | E12: =COUNTIF('Other'!$I:$I,"Not Tested") | F12: =COUNTIF('Other'!$I:$I,"Not Implemented") | G12: =SUM(B12:F12) | H12: =IF(G12>0,B12/G12,0)
A13: Technical Updates | B13: =COUNTIF('Technical Updates'!$I:$I,"Passed") | C13: =COUNTIF('Technical Updates'!$I:$I,"Failed") | D13: =COUNTIF('Technical Updates'!$I:$I,"Partially Passed") | E13: =COUNTIF('Technical Updates'!$I:$I,"Not Tested") | F13: =COUNTIF('Technical Updates'!$I:$I,"Not Implemented") | G13: =SUM(B13:F13) | H13: =IF(G13>0,B13/G13,0)
A14: Deep Payment | B14: =COUNTIF('Deep Payment'!$I:$I,"Passed") | C14: =COUNTIF('Deep Payment'!$I:$I,"Failed") | D14: =COUNTIF('Deep Payment'!$I:$I,"Partially Passed") | E14: =COUNTIF('Deep Payment'!$I:$I,"Not Tested") | F14: =COUNTIF('Deep Payment'!$I:$I,"Not Implemented") | G14: =SUM(B14:F14) | H14: =IF(G14>0,B14/G14,0)
A15: PoS Transactions | B15: =COUNTIF('PoS Transactions'!$I:$I,"Passed") | C15: =COUNTIF('PoS Transactions'!$I:$I,"Failed") | D15: =COUNTIF('PoS Transactions'!$I:$I,"Partially Passed") | E15: =COUNTIF('PoS Transactions'!$I:$I,"Not Tested") | F15: =COUNTIF('PoS Transactions'!$I:$I,"Not Implemented") | G15: =SUM(B15:F15) | H15: =IF(G15>0,B15/G15,0)
A16: Setup & Admin | B16: =COUNTIF('Setup & Admin'!$I:$I,"Passed") | C16: =COUNTIF('Setup & Admin'!$I:$I,"Failed") | D16: =COUNTIF('Setup & Admin'!$I:$I,"Partially Passed") | E16: =COUNTIF('Setup & Admin'!$I:$I,"Not Tested") | F16: =COUNTIF('Setup & Admin'!$I:$I,"Not Implemented") | G16: =SUM(B16:F16) | H16: =IF(G16>0,B16/G16,0)
A17: Transaction Operations | B17: =COUNTIF('Transaction Operations'!$I:$I,"Passed") | C17: =COUNTIF('Transaction Operations'!$I:$I,"Failed") | D17: =COUNTIF('Transaction Operations'!$I:$I,"Partially Passed") | E17: =COUNTIF('Transaction Operations'!$I:$I,"Not Tested") | F17: =COUNTIF('Transaction Operations'!$I:$I,"Not Implemented") | G17: =SUM(B17:F17) | H17: =IF(G17>0,B17/G17,0)
A18: Registration | B18: =COUNTIF('Registration'!$I:$I,"Passed") | C18: =COUNTIF('Registration'!$I:$I,"Failed") | D18: =COUNTIF('Registration'!$I:$I,"Partially Passed") | E18: =COUNTIF('Registration'!$I:$I,"Not Tested") | F18: =COUNTIF('Registration'!$I:$I,"Not Implemented") | G18: =SUM(B18:F18) | H18: =IF(G18>0,B18/G18,0)
A19: Top Up & Cash In | B19: =COUNTIF('Top Up & Cash In'!$I:$I,"Passed") | C19: =COUNTIF('Top Up & Cash In'!$I:$I,"Failed") | D19: =COUNTIF('Top Up & Cash In'!$I:$I,"Partially Passed") | E19: =COUNTIF('Top Up & Cash In'!$I:$I,"Not Tested") | F19: =COUNTIF('Top Up & Cash In'!$I:$I,"Not Implemented") | G19: =SUM(B19:F19) | H19: =IF(G19>0,B19/G19,0)
A20: Balances & Wallet Consistency | B20: =COUNTIF('Balances & Wallet Consistency'!$I:$I,"Passed") | C20: =COUNTIF('Balances & Wallet Consistency'!$I:$I,"Failed") | D20: =COUNTIF('Balances & Wallet Consistency'!$I:$I,"Partially Passed") | E20: =COUNTIF('Balances & Wallet Consistency'!$I:$I,"Not Tested") | F20: =COUNTIF('Balances & Wallet Consistency'!$I:$I,"Not Implemented") | G20: =SUM(B20:F20) | H20: =IF(G20>0,B20/G20,0)
A21: Products | B21: =COUNTIF('Products'!$I:$I,"Passed") | C21: =COUNTIF('Products'!$I:$I,"Failed") | D21: =COUNTIF('Products'!$I:$I,"Partially Passed") | E21: =COUNTIF('Products'!$I:$I,"Not Tested") | F21: =COUNTIF('Products'!$I:$I,"Not Implemented") | G21: =SUM(B21:F21) | H21: =IF(G21>0,B21/G21,0)
A22: Login | B22: =COUNTIF('Login'!$I:$I,"Passed") | C22: =COUNTIF('Login'!$I:$I,"Failed") | D22: =COUNTIF('Login'!$I:$I,"Partially Passed") | E22: =COUNTIF('Login'!$I:$I,"Not Tested") | F22: =COUNTIF('Login'!$I:$I,"Not Implemented") | G22: =SUM(B22:F22) | H22: =IF(G22>0,B22/G22,0)
A23: Integrations | B23: =COUNTIF('Integrations'!$I:$I,"Passed") | C23: =COUNTIF('Integrations'!$I:$I,"Failed") | D23: =COUNTIF('Integrations'!$I:$I,"Partially Passed") | E23: =COUNTIF('Integrations'!$I:$I,"Not Tested") | F23: =COUNTIF('Integrations'!$I:$I,"Not Implemented") | G23: =SUM(B23:F23) | H23: =IF(G23>0,B23/G23,0)
A24: RMS | B24: =COUNTIF('RMS'!$I:$I,"Passed") | C24: =COUNTIF('RMS'!$I:$I,"Failed") | D24: =COUNTIF('RMS'!$I:$I,"Partially Passed") | E24: =COUNTIF('RMS'!$I:$I,"Not Tested") | F24: =COUNTIF('RMS'!$I:$I,"Not Implemented") | G24: =SUM(B24:F24) | H24: =IF(G24>0,B24/G24,0)
A25: Multi-Omnibus | B25: =COUNTIF('Multi-Omnibus'!$I:$I,"Passed") | C25: =COUNTIF('Multi-Omnibus'!$I:$I,"Failed") | D25: =COUNTIF('Multi-Omnibus'!$I:$I,"Partially Passed") | E25: =COUNTIF('Multi-Omnibus'!$I:$I,"Not Tested") | F25: =COUNTIF('Multi-Omnibus'!$I:$I,"Not Implemented") | G25: =SUM(B25:F25) | H25: =IF(G25>0,B25/G25,0)
A26: Roles & Permissions | B26: =COUNTIF('Roles & Permissions'!$I:$I,"Passed") | C26: =COUNTIF('Roles & Permissions'!$I:$I,"Failed") | D26: =COUNTIF('Roles & Permissions'!$I:$I,"Partially Passed") | E26: =COUNTIF('Roles & Permissions'!$I:$I,"Not Tested") | F26: =COUNTIF('Roles & Permissions'!$I:$I,"Not Implemented") | G26: =SUM(B26:F26) | H26: =IF(G26>0,B26/G26,0)
A27: Dashboard & Wallets | B27: =COUNTIF('Dashboard & Wallets'!$I:$I,"Passed") | C27: =COUNTIF('Dashboard & Wallets'!$I:$I,"Failed") | D27: =COUNTIF('Dashboard & Wallets'!$I:$I,"Partially Passed") | E27: =COUNTIF('Dashboard & Wallets'!$I:$I,"Not Tested") | F27: =COUNTIF('Dashboard & Wallets'!$I:$I,"Not Implemented") | G27: =SUM(B27:F27) | H27: =IF(G27>0,B27/G27,0)
A28: Sub-Wallets | B28: =COUNTIF('Sub-Wallets'!$I:$I,"Passed") | C28: =COUNTIF('Sub-Wallets'!$I:$I,"Failed") | D28: =COUNTIF('Sub-Wallets'!$I:$I,"Partially Passed") | E28: =COUNTIF('Sub-Wallets'!$I:$I,"Not Tested") | F28: =COUNTIF('Sub-Wallets'!$I:$I,"Not Implemented") | G28: =SUM(B28:F28) | H28: =IF(G28>0,B28/G28,0)
A29: Adjustments & Reversals | B29: =COUNTIF('Adjustments & Reversals'!$I:$I,"Passed") | C29: =COUNTIF('Adjustments & Reversals'!$I:$I,"Failed") | D29: =COUNTIF('Adjustments & Reversals'!$I:$I,"Partially Passed") | E29: =COUNTIF('Adjustments & Reversals'!$I:$I,"Not Tested") | F29: =COUNTIF('Adjustments & Reversals'!$I:$I,"Not Implemented") | G29: =SUM(B29:F29) | H29: =IF(G29>0,B29/G29,0)
A30: Reconciliation | B30: =COUNTIF('Reconciliation'!$I:$I,"Passed") | C30: =COUNTIF('Reconciliation'!$I:$I,"Failed") | D30: =COUNTIF('Reconciliation'!$I:$I,"Partially Passed") | E30: =COUNTIF('Reconciliation'!$I:$I,"Not Tested") | F30: =COUNTIF('Reconciliation'!$I:$I,"Not Implemented") | G30: =SUM(B30:F30) | H30: =IF(G30>0,B30/G30,0)
A31: Profile & Manage Accounts | B31: =COUNTIF('Profile & Manage Accounts'!$I:$I,"Passed") | C31: =COUNTIF('Profile & Manage Accounts'!$I:$I,"Failed") | D31: =COUNTIF('Profile & Manage Accounts'!$I:$I,"Partially Passed") | E31: =COUNTIF('Profile & Manage Accounts'!$I:$I,"Not Tested") | F31: =COUNTIF('Profile & Manage Accounts'!$I:$I,"Not Implemented") | G31: =SUM(B31:F31) | H31: =IF(G31>0,B31/G31,0)
A32: Money Request | B32: =COUNTIF('Money Request'!$I:$I,"Passed") | C32: =COUNTIF('Money Request'!$I:$I,"Failed") | D32: =COUNTIF('Money Request'!$I:$I,"Partially Passed") | E32: =COUNTIF('Money Request'!$I:$I,"Not Tested") | F32: =COUNTIF('Money Request'!$I:$I,"Not Implemented") | G32: =SUM(B32:F32) | H32: =IF(G32>0,B32/G32,0)
A33: Forgot Password | B33: =COUNTIF('Forgot Password'!$I:$I,"Passed") | C33: =COUNTIF('Forgot Password'!$I:$I,"Failed") | D33: =COUNTIF('Forgot Password'!$I:$I,"Partially Passed") | E33: =COUNTIF('Forgot Password'!$I:$I,"Not Tested") | F33: =COUNTIF('Forgot Password'!$I:$I,"Not Implemented") | G33: =SUM(B33:F33) | H33: =IF(G33>0,B33/G33,0)
A34: Bill Payment | B34: =COUNTIF('Bill Payment'!$I:$I,"Passed") | C34: =COUNTIF('Bill Payment'!$I:$I,"Failed") | D34: =COUNTIF('Bill Payment'!$I:$I,"Partially Passed") | E34: =COUNTIF('Bill Payment'!$I:$I,"Not Tested") | F34: =COUNTIF('Bill Payment'!$I:$I,"Not Implemented") | G34: =SUM(B34:F34) | H34: =IF(G34>0,B34/G34,0)
A35: Platform & System | B35: =COUNTIF('Platform & System'!$I:$I,"Passed") | C35: =COUNTIF('Platform & System'!$I:$I,"Failed") | D35: =COUNTIF('Platform & System'!$I:$I,"Partially Passed") | E35: =COUNTIF('Platform & System'!$I:$I,"Not Tested") | F35: =COUNTIF('Platform & System'!$I:$I,"Not Implemented") | G35: =SUM(B35:F35) | H35: =IF(G35>0,B35/G35,0)
A36: Bill Management (Creation) | B36: =COUNTIF('Bill Management (Creation)'!$I:$I,"Passed") | C36: =COUNTIF('Bill Management (Creation)'!$I:$I,"Failed") | D36: =COUNTIF('Bill Management (Creation)'!$I:$I,"Partially Passed") | E36: =COUNTIF('Bill Management (Creation)'!$I:$I,"Not Tested") | F36: =COUNTIF('Bill Management (Creation)'!$I:$I,"Not Implemented") | G36: =SUM(B36:F36) | H36: =IF(G36>0,B36/G36,0)
A37: Transaction Log | B37: =COUNTIF('Transaction Log'!$I:$I,"Passed") | C37: =COUNTIF('Transaction Log'!$I:$I,"Failed") | D37: =COUNTIF('Transaction Log'!$I:$I,"Partially Passed") | E37: =COUNTIF('Transaction Log'!$I:$I,"Not Tested") | F37: =COUNTIF('Transaction Log'!$I:$I,"Not Implemented") | G37: =SUM(B37:F37) | H37: =IF(G37>0,B37/G37,0)
A38: KYC - KYB - AML | B38: =COUNTIF('KYC - KYB - AML'!$I:$I,"Passed") | C38: =COUNTIF('KYC - KYB - AML'!$I:$I,"Failed") | D38: =COUNTIF('KYC - KYB - AML'!$I:$I,"Partially Passed") | E38: =COUNTIF('KYC - KYB - AML'!$I:$I,"Not Tested") | F38: =COUNTIF('KYC - KYB - AML'!$I:$I,"Not Implemented") | G38: =SUM(B38:F38) | H38: =IF(G38>0,B38/G38,0)
A39: QR Payment | B39: =COUNTIF('QR Payment'!$I:$I,"Passed") | C39: =COUNTIF('QR Payment'!$I:$I,"Failed") | D39: =COUNTIF('QR Payment'!$I:$I,"Partially Passed") | E39: =COUNTIF('QR Payment'!$I:$I,"Not Tested") | F39: =COUNTIF('QR Payment'!$I:$I,"Not Implemented") | G39: =SUM(B39:F39) | H39: =IF(G39>0,B39/G39,0)
A40: Bank Transfer & Cash Out | B40: =COUNTIF('Bank Transfer & Cash Out'!$I:$I,"Passed") | C40: =COUNTIF('Bank Transfer & Cash Out'!$I:$I,"Failed") | D40: =COUNTIF('Bank Transfer & Cash Out'!$I:$I,"Partially Passed") | E40: =COUNTIF('Bank Transfer & Cash Out'!$I:$I,"Not Tested") | F40: =COUNTIF('Bank Transfer & Cash Out'!$I:$I,"Not Implemented") | G40: =SUM(B40:F40) | H40: =IF(G40>0,B40/G40,0)
A41: JIT | B41: =COUNTIF('JIT'!$I:$I,"Passed") | C41: =COUNTIF('JIT'!$I:$I,"Failed") | D41: =COUNTIF('JIT'!$I:$I,"Partially Passed") | E41: =COUNTIF('JIT'!$I:$I,"Not Tested") | F41: =COUNTIF('JIT'!$I:$I,"Not Implemented") | G41: =SUM(B41:F41) | H41: =IF(G41>0,B41/G41,0)
A42: Notifications | B42: =COUNTIF('Notifications'!$I:$I,"Passed") | C42: =COUNTIF('Notifications'!$I:$I,"Failed") | D42: =COUNTIF('Notifications'!$I:$I,"Partially Passed") | E42: =COUNTIF('Notifications'!$I:$I,"Not Tested") | F42: =COUNTIF('Notifications'!$I:$I,"Not Implemented") | G42: =SUM(B42:F42) | H42: =IF(G42>0,B42/G42,0)
A43: Wallet Configuration | B43: =COUNTIF('Wallet Configuration'!$I:$I,"Passed") | C43: =COUNTIF('Wallet Configuration'!$I:$I,"Failed") | D43: =COUNTIF('Wallet Configuration'!$I:$I,"Partially Passed") | E43: =COUNTIF('Wallet Configuration'!$I:$I,"Not Tested") | F43: =COUNTIF('Wallet Configuration'!$I:$I,"Not Implemented") | G43: =SUM(B43:F43) | H43: =IF(G43>0,B43/G43,0)
...

Sheet Other
A1: TC ID | B1: Sub-Area | C1: Source ID | D1: Title | E1: Priority | F1: Preconditions | G1: Steps | H1: Expected Result | I1: Status | J1: Test Type | K1: Interface | L1: Source | M1: Jira Ref | N1: Automated | O1: Automated By | P1: Channel
A2: EMI-B2B-2976 | C2: EMI-TC-4395 | D2: Assure that the name is removed from the form | E2: Critical | G2: 1. Navigate to the app 2. Login with a valid username and password 3. Create new user 4.check the form | H2: The name should be removed from the form | I2: Not Tested | J2: Functional | K2: Web | L2: AIO (Jira) | M2: EMI-4847 | N2: No | P2: B2B
A3: EMI-B2B-2977 | C3: EMI-TC-4396 | D3: Assure that the national ID/Iqama field exists | E3: Critical | G3: 1. Navigate to the app 2. Login with a valid username and password 3. Create new user 4.check the form | H3: The national ID/iqama should be removed from the form | I3: Not Tested | J3: Functional | K3: Web | L3: AIO (Jira) | M3: EMI-4847 | N3: No | P3: B2B
A4: EMI-B2B-2982 | C4: EMI-TC-4401 | D4: Assure that the user receives notification on the transactions | E4: Critical | G4: 1. Navigate to the app 2. Login with a valid username and password 3. create a transCTION | H4: A notification should be sent to the user | I4: Not Tested | J4: Functional | K4: Web | L4: AIO (Jira) | M4: EMI-4770 | N4: No | P4: B2B
A5: EMI-B2B-2988 | C5: EMI-TC-4938 | D5: ANB connector retrieves transaction statements for a given date range | E5: Critical | F5: ANB connector is authenticated. Transactions exist for the period 2025-01-01 to 2025-01-31. | G5: Call the ANB connector to retrieve transactions for January 2025. | H5: All transactions within the date range are returned. Response contains the expected fields. No transactions outside the range are included. | I5: Not Tested | J5: Functional | K5: Web | L5: AIO (Jira) | M5: EMI-4619 | N5: No | P5: B2B
A6: EMI-B2B-2989 | C6: EMI-TC-4939 | D6: Hyperpay connector retrieves transaction statements for a given date range | E6: Critical | F6: Hyperpay connector is authenticated. Transactions exist for the period 2025-01-01 to 2025-01-31. | G6: Call the Hyperpay connector to retrieve transactions for January 2025. | H6: All transactions within the date range are returned. Response contains expected fields. No out-of-range transactions included. | I6: Not Tested | J6: Functional | K6: Web | L6: AIO (Jira) | M6: EMI-4619 | N6: No | P6: B2B
A7: EMI-B2B-2993 | C7: EMI-TC-4943 | D7: Hyperpay transaction fields map correctly to all unified schema fields | E7: Critical | F7: Hyperpay raw transaction response available. Unified schema fields predefined. | G7: Run the Hyperpay mapping logic on a sample transaction. | H7: Every unified schema field is populated correctly from the Hyperpay response. Field names and data types match the schema definition. | I7: Not Tested | J7: Functional | K7: Web | L7: AIO (Jira) | M7: EMI-4619 | N7: No | P7: B2B
A8: EMI-B2B-2996 | C8: EMI-TC-4946 | D8: Mapped ANB transactions are stored in the datastore correctly | E8: Critical | F8: ANB transactions have been retrieved and mapped to the unified schema. | G8: Trigger the storage step for the mapped ANB transactions. | H8: All mapped records are persisted in the datastore. Each record is retrievable and contains the correct unified schema field values. Source is identifiable as ANB. | I8: Not Tested | J8: Functional | K8: Web | L8: AIO (Jira) | M8: EMI-4619 | N8: No | P8: B2B
A9: EMI-B2B-2997 | C9: EMI-TC-4947 | D9: Mapped Hyperpay transactions are stored in the datastore correctly | E9: Critical | F9: Hyperpay transactions have been retrieved and mapped to the unified schema. | G9: Trigger the storage step for the mapped Hyperpay transactions. | H9: All mapped records are persisted. Each record is retrievable with correct values. Source is identifiable as Hyperpay. | I9: Not Tested | J9: Functional | K9: Web | L9: AIO (Jira) | M9: EMI-4619 | N9: No | P9: B2B
A10: EMI-B2B-3002 | C10: EMI-TC-5875 | D10: Run GET /api/internal/v1/configs/providers | E10: Critical | F10: Access to the internal configuration API at /api/internal/v1/configs/providers, with a valid authorisation token and at least one provider configured. | G10: 1. Call GET /api/internal/v1/configs/providers with valid input and a valid token 2. Check the status code and the response body 3. Compare the result against the stored configuration 4. Call it with invalid input 5. Call it with no token and with an unauthorised token 6. Call it twice with the same input | H10: 1. GET /api/internal/v1/configs/providers returns a success response for a valid, authorised request and does list the configured providers. 2. The response body is well formed and its values match the stored configuration. 3. Only the providers the caller is entitled to see are returned. 4. Invalid input is refused with a clear validation error, not a server error. 5. A call with no token, or with a token lacking the privilege, is refused with 401 or 403 and returns no configuration data. 6. Repeating the same create does not silently produce a duplicate provider. 7. No credential or secret held in the provider configuration is returned in clear. | I10: Not Tested | J10: Functional | K10: API | L10: AIO (Jira) | M10: EMI-4836 | N10: No | P10: B2B
A11: EMI-B2B-3003 | C11: EMI-TC-5876 | D11: Run GET /api/internal/v1/configs/providers/{providerId} | E11: Critical | F11: Access to the internal configuration API at /api/internal/v1/configs/providers/{providerId}, with a valid authorisation token and at least one provider configured. | G11: 1. Call GET /api/internal/v1/configs/providers/{providerId} with valid input and a valid token 2. Check the status code and the response body 3. Compare the result against the stored configuration 4. Call it with invalid input 5. Call it with no token and with an unauthorised token 6. Call it for a provider that does not exist | H11: 1. GET /api/internal/v1/configs/providers/{providerId} returns a success response for a valid, authorised request and does read one provider. 2. The response body is well formed and its values match the stored configuration. 3. Only the providers the caller is entitled to see are returned. 4. Invalid input is refused with a clear validation error, not a server error. 5. A call with no token, or with a token lacking the privilege, is refused with 401 or 403 and returns no configuration data. 6. A request for a provider that does not exist returns a clear not-found response rather than a server error or an empty success. 7. No credential or secret held in the provider configuration is returned in clear. | I11: Not Tested | J11: Functional | K11: API | L11: AIO (Jira) | M11: EMI-4836 | N11: No | P11: B2B
A12: EMI-B2B-3004 | C12: EMI-TC-5877 | D12: Run POST /api/internal/v1/configs/providers | E12: Critical | F12: Access to the internal configuration API at /api/internal/v1/configs/providers, with a valid authorisation token and at least one provider configured. | G12: 1. Call POST /api/internal/v1/configs/providers with valid input and a valid token 2. Check the status code and the response body 3. Compare the result against the stored configuration 4. Call it with invalid input 5. Call it with no token and with an unauthorised token 6. Call it twice with the same input | H12: 1. POST /api/internal/v1/configs/providers returns a success response for a valid, authorised request and does create a provider. 2. The response body is well formed and its values match the stored configuration. 3. The change is persisted and reads back identically on a subsequent GET. 4. Invalid input is refused with a clear validation error and nothing partial is written. 5. A call with no token, or with a token lacking the privilege, is refused with 401 or 403 and returns no configuration data. 6. Repeating the same create does not silently produce a duplicate provider. 7. No credential or secret held in the provider configuration is returned in clear. | I12: Not Tested | J12: Functional | K12: API | L12: AIO (Jira) | M12: EMI-4836 | N12: No | P12: B2B
A13: EMI-B2B-3005 | C13: EMI-TC-5878 | D13: Run PUT /api/internal/v1/configs/providers/{providerId} | E13: Critical | F13: Access to the internal configuration API at /api/internal/v1/configs/providers/{providerId}, with a valid authorisation token and at least one provider configured. | G13: 1. Call PUT /api/internal/v1/configs/providers/{providerId} with valid input and a valid token 2. Check the status code and the response body 3. Compare the result against the stored configuration 4. Call it with invalid input 5. Call it with no token and with an unauthorised token 6. Call it for a provider that does not exist | H13: 1. PUT /api/internal/v1/configs/providers/{providerId} returns a success response for a valid, authorised request and does update a provider. 2. The response body is well formed and its values match the stored configuration. 3. The change is persisted and reads back identically on a subsequent GET. 4. Invalid input is refused with a clear validation error and nothing partial is written. 5. A call with no token, or with a token lacking the privilege, is refused with 401 or 403 and returns no configuration data. 6. A request for a provider that does not exist returns a clear not-found response rather than a server error or an empty success. 7. No credential or secret held in the provider configuration is returned in clear. | I13: Not Tested | J13: Functional | K13: API | L13: AIO (Jira) | M13: EMI-4836 | N13: No | P13: B2B
A14: EMI-B2B-3006 | C14: EMI-TC-5879 | D14: Run GET /v2/info/{transactionId} | E14: Critical | F14: Access to GET /v2/info/{transactionId} with a valid token and a known transaction. | G14: 1. Call the endpoint for a known transaction 2. Check the status and the response fields 3. Compare each value against the transaction record 4. Call it for a transaction that does not exist 5. Call it for a transaction belonging to another account 6. Call it with no token | H14: 1. The endpoint returns a success response for a valid, authorised request. 2. Every field returned matches the underlying transaction record. 3. A transaction that does not exist returns a clear not-found response, not a server error and not an empty success. 4. A transaction belonging to another account is refused, and the response does not reveal whether it exists. 5. A call with no token is refused with 401 or 403 and returns no data. 6. The response follows the standardised field format used by the other endpoints. | I14: Not Tested | J14: Functional | K14: API | L14: AIO (Jira) | M14: EMI-4836 | N14: No | P14: B2B
A15: EMI-B2B-3007 | C15: EMI-TC-5880 | D15: Run GET /v2/companies/address/{crNumber} | E15: Critical | F15: Access to GET /v2/companies/address/{crNumber} with a valid token and a CR number known to exist. | G15: 1. Call GET /v2/companies/address/{crNumber} for a CR number known to exist 2. Check the status and every field returned 3. Compare against the source registry data 4. Call it for a CR number that does not exist 5. Call it with a malformed CR number 6. Call it with no token and with an unauthorised one | H15: 1. The endpoint returns the company address for a CR number that exists. 2. Every field matches the source registry data, with no truncation or reformatting. 3. A CR number that does not exist returns a clear not-found response, not a server error and not an empty success that looks like a real answer. 4. A malformed CR number is refused with a validation error. 5. A call with no token, or one lacking the privilege, is refused and returns no data. 6. The CR number is not exposed anywhere it would be logged in clear. | I15: Not Tested | J15: Functional | K15: API | L15: AIO (Jira) | M15: EMI-4836 | N15: No | P15: B2B
A16: EMI-B2B-3008 | C16: EMI-TC-5881 | D16: Run GET /v2/companies/{crNumber} | E16: Critical | F16: Access to GET /v2/companies/{crNumber} with a valid token and a CR number known to exist. | G16: 1. Call GET /v2/companies/{crNumber} for a CR number known to exist 2. Check the status and every field returned 3. Compare against the source registry data 4. Call it for a CR number that does not exist 5. Call it with a malformed CR number 6. Call it with no token and with an unauthorised one | H16: 1. The endpoint returns the company record for a CR number that exists. 2. Every field matches the source registry data, with no truncation or reformatting. 3. A CR number that does not exist returns a clear not-found response, not a server error and not an empty success that looks like a real answer. 4. A malformed CR number is refused with a validation error. 5. A call with no token, or one lacking the privilege, is refused and returns no data. 6. The CR number is not exposed anywhere it would be logged in clear. | I16: Not Tested | J16: Functional | K16: API | L16: AIO (Jira) | M16: EMI-4836 | N16: No | P16: B2B
... A21: EMI-B2B-3012 | C21: EMI-TC-7885 | D21: Verify standardized response fields for each transaction endpoint | E21: High | F21: Access to every transaction endpoint in the new response format, with the agreed standard field set documented. | G21: the user is authenticated | H21: 1. Every transaction endpoint returns the agreed standard fields. 2. The field names are identical across endpoints — the same value is not called one thing on one endpoint and something else on another. 3. Types and formats are consistent: amounts to two decimal places, dates in the same format, statuses from the same enumeration. 4. No endpoint omits a field the standard requires. 5. Error responses follow the same standard shape. 6. A client reading one endpoint can read the others without special-casing. | I21: Not Tested | J21: Functional | K21: API | L21: AIO (Jira) | M21: EMI-5490 | N21: No | P21: B2B
A22: EMI-B2B-3013 | C22: EMI-TC-8404 | D22: Risk/compliance restrictions still apply | E22: Medium | G22: 1. Auto-activate a profile 2. Admin applies a compliance restriction | H22: Restriction is enforced; relevant operations are blocked | I22: Not Tested | J22: Functional | K22: Web | L22: AIO (Jira) | N22: No | P22: B2B
A23: EMI-B2B-3014 | C23: EMI-TC-8627 | D23: Same as EMI-5782 TC1–TC23 | E23: Medium | G23: Execute on Android instead of iOS | H23: Same expected results on Android | I23: Not Tested | J23: Functional | K23: Web | L23: AIO (Jira) | M23: EMI-5780 | N23: No | P23: B2B
A24: EMI-B2B-2985 | C24: EMI-TC-4935 | D24: Hyperpay connector initialises and authenticates successfully | E24: Critical | F24: Valid Hyperpay API credentials are configured. | G24: Initialise the Hyperpay connector and trigger an authentication handshake. | H24: Connector initialises without error. Authentication succeeds and a valid connection state is established. | I24: Not Tested | J24: Negative | K24: Web | L24: AIO (Jira) | M24: EMI-4619 | N24: No | P24: B2B
A25: EMI-B2B-2992 | C25: EMI-TC-4942 | D25: ANB transaction fields map correctly to all unified schema fields | E25: Critical | F25: ANB raw transaction response available. Unified schema fields predefined. | G25: Run the ANB mapping logic on a sample transaction. | H25: Every unified schema field is populated with the correct value from the ANB response. No field is missing, null, or mapped to the wrong source field. | I25: Not Tested | J25: Negative | K25: Web | L25: AIO (Jira) | M25: EMI-4619 | N25: No | P25: B2B
A26: EMI-B2B-2991 | C26: EMI-TC-4941 | D26: Connector retries and fails with a clear error on repeated source unavailability | E26: High | F26: Source API (ANB or Hyperpay) returns 503 repeatedly. | G26: Trigger transaction retrieval when the source is consistently unavailable. | H26: Connector retries the configured number of times then throws a retrieval failure error. Failure is logged with source name, timestamp, and HTTP status. No partial data is processed. | I26: Not Tested | J26: Negative | K26: Web | L26: AIO (Jira) | M26: EMI-4619 | N26: No | P26: B2B
A27: EMI-B2B-2995 | C27: EMI-TC-4945 | D27: Mapping fails with a clear error when a mandatory schema field is absent in source | E27: High | F27: A source transaction is missing a mandatory unified schema field (e.g. transaction ID or amount). | G27: Run mapping on the transaction with the missing mandatory field. | H27: Mapping throws a validation error identifying the missing mandatory field. The record is not passed to storage. Other records in the batch are unaffected. | I27: Not Tested | J27: Negative | K27: Web | L27: AIO (Jira) | M27: EMI-4619 | N27: No | P27: B2B
A28: EMI-B2B-2999 | C28: EMI-TC-4949 | D28: Storage failure is logged and does not silently drop data | E28: High | F28: Datastore is temporarily unavailable during the storage step. | G28: Trigger the storage step while the datastore is down. | H28: Storage error is caught and logged with transaction batch details. Data is not silently dropped. An alert or retry mechanism is triggered. System remains stable. | I28: Not Tested | J28: Negative | K28: Web | L28: AIO (Jira) | M28: EMI-4619 | N28: No | P28: B2B
A29: EMI-B2B-2994 | C29: EMI-TC-4944 | D29: Optional schema field absent in source maps to null without error | E29: Medium | F29: A source transaction is missing an optional unified schema field (e.g. reference note). | G29: Run mapping on the transaction with the missing optional field. | H29: Mapping completes successfully. The optional field is set to null in the mapped record. Mandatory fields are unaffected. No exception thrown. | I29: Not Tested | J29: Negative | K29: Web | L29: AIO (Jira) | M29: EMI-4619 | N29: No | P29: B2B
A30: EMI-B2B-2984 | C30: EMI-TC-4934 | D30: ANB connector initialises and authenticates successfully | E30: Critical | F30: Valid ANB API credentials (key, secret, base URL) are configured. | G30: Initialise the ANB connector and trigger an authentication handshake. | H30: Connector initialises without error. Authentication succeeds and a valid session token or connection state is returned. | I30: Not Tested | J30: Security | K30: Web | L30: AIO (Jira) | M30: EMI-4619 | N30: No | P30: B2B
A31: EMI-B2B-2981 | C31: EMI-TC-4400 | D31: Assure that the translation messages code are not duplicated | E31: Critical | G31: 1. Navigate to the app 2. Login with a valid username and password 3. Navigate to the transalation module 4.Create a message with the same code | H31: Validation should be displayed | I31: Not Tested | J31: Integration | K31: Web | L31: AIO (Jira) | M31: EMI-4838 | N31: No | P31: B2B
A32: EMI-B2B-2986 | C32: EMI-TC-4936 | D32: ANB connector fails gracefully with invalid credentials | E32: High | F32: ANB connector configured with incorrect API credentials. | G32: Attempt to initialise and authenticate the ANB connector. | H32: Connector throws a clear authentication error. No silent failure. Error message identifies the credential issue without exposing secrets. | I32: Not Tested | J32: Integration | K32: Web | L32: AIO (Jira) | M32: EMI-4619 | N32: No | P32: B2B
A33: EMI-B2B-2987 | C33: EMI-TC-4937 | D33: Hyperpay connector fails gracefully when endpoint is unreachable | E33: High | F33: Hyperpay base URL is set to an unreachable host. | G33: Attempt to initialise and connect the Hyperpay connector. | H33: Connector throws a connection timeout or unreachable host error within the configured timeout window. System remains stable. | I33: Not Tested | J33: Integration | K33: API | L33: AIO (Jira) | M33: EMI-4619 | N33: No | P33: B2B
A34: EMI-B2B-2998 | C34: EMI-TC-4948 | D34: Duplicate transactions are not stored twice on re-ingestion | E34: High | F34: A batch of transactions has already been stored. The same batch is submitted again. | G34: Run the full connector pipeline (retrieve, map, store) a second time with the same data. | H34: Duplicate records are detected and skipped. No duplicate entries appear in the datastore. Idempotency is enforced at the storage layer. | I34: Not Tested | J34: Integration | K34: Web | L34: AIO (Jira) | M34: EMI-4619 | N34: No | P34: B2B
A35: EMI-B2B-2990 | C35: EMI-TC-4940 | D35: Retrieval returns empty list gracefully when no transactions exist for the period | E35: Medium | F35: No transactions exist in either source for the requested date range. | G35: Call both connectors for a date range with no transaction data. | H35: Both connectors return an empty list without error. No exception is thrown. System proceeds to the mapping stage with empty input gracefully. | I35: Not Tested | J35: Integration | K35: Web | L35: AIO (Jira) | M35: EMI-4619 | N35: No | P35: B2B
A36: EMI-B2B-2978 | C36: EMI-TC-4397 | D36: Assure that Nafath screen displays to the user on creating a new user | E36: Critical | G36: 1. Navigate to the app 2. Login with a valid username and password 3. Create new user 4.check the form 5. Fill the form and submit | H36: Nafath screen should be displayed to the user to confirm the ID | I36: Not Tested | J36: Usability | K36: Web | L36: AIO (Jira) | M36: EMI-4847 | N36: No | P36: B2B
A37: EMI-B2B-2979 | C37: EMI-TC-4398 | D37: Verify Nafath count down | E37: Critical | G37: 1. Navigate to the app 2. Login with a valid username and password 3. Create new user 4.check the form 5. Fill the form and submit | H37: Nafath screen should be displayed to the user to confirm the ID | I37: Not Tested | J37: Usability | K37: Web | L37: AIO (Jira) | M37: EMI-4847 | N37: No | P37: B2B
A38: EMI-B2B-2980 | C38: EMI-TC-4399 | D38: Assure that upon verify nafath the new user is created | E38: Critical | G38: 1. Navigate to the app 2. Login with a valid username and password 3. Create new user 4.check the form 5. Fill the form and submit 6. Verify Nafath | H38: 1.The user should be created and displayed at the list 2. Creation email should be sent to the user | I38: Not Tested | J38: Usability | K38: Web | L38: AIO (Jira) | M38: EMI-4847 | N38: No | P38: B2B
A39: EMI-B2B-2983 | C39: EMI-TC-4402 | D39: Assure that the module displayed to the business | E39: Critical | G39: 1. Navigate to the app 2. Login with a valid username and password 3. create a transCTION | H39: The module should be displayed | I39: Not Tested | J39: Usability | K39: Web | L39: AIO (Jira) | M39: EMI-4701 | N39: No | P39: B2B
A40: EMI-B2B-3001 | C40: EMI-TC-5874 | D40: Assure that the system displays in dark mode correctly | E40: High | F40: A signed-in session able to reach every main screen, with the interface set to dark mode. | G40: 1. Set the interface to dark mode 2. Open every main screen in turn 3. Check each for legibility and correct rendering 4. Open dialogs, dropdowns, tables and any embedded document 5. Exercise a full flow end to end in dark mode 6. Switch back and forth mid-flow | H40: 1. Every screen renders in dark mode — no screen, panel, dialog or embedded document falls back to the light theme. 2. All text stays legible against its background, including validation messages, disabled controls, table headers and totals. 3. Icons, borders, input outlines and separators remain visible rather than disappearing into the background. 4. Every control remains usable and its state — enabled, disabled, selected — stays distinguishable. 5. A full flow completes end to end in dark mode with the same result as in light mode. 6. Switching theme mid-flow keeps the user on the same screen with their data intact, and the choice persists across screens and a refresh. 7. NOTE for review: EMI-TC-5873 and EMI-TC-5874 differ only in wording ("works" versus "displays") — confirm whether one should be retired in AIO. | I40: Not Tested | J40: Usability | K40: Web | L40: AIO (Jira) | M40: EMI-5293 | N40: No | P40: B2B
A41: EMI-B2B-4836 | B41: B. Functionality | C41: RO-16 | D41: Advance to the Business Info step after entering the correct OTP | E41: High | G41: Load the OTP popup | H41: The Business Info step is shown | I41: Not Tested | J41: Functional | K41: Web | L41: Project docs | N41: No | P41: B2B
A42: EMI-B2B-8671 | B42: Manual Test Cases — B2B Transactions | C42: BM-11 | D42: Delete a beneficiary | E42: High | G42: Select Delete on an existing beneficiary; confirm | H42: Beneficiary is removed from the list; success message shown | I42: Not Tested | J42: Functional | K42: Web | L42: Project docs | N42: Yes | O42: BeneficiaryManagement/functional/BeneficiaryManagementFlow.spec.ts | P42: B2B
A43: EMI-B2B-8214 | B43: Manual Test Cases — B2B Transactions | C43: CB-03 | D43: Discount type "None" is default and hides amount field | E43: High | G43: Open Add Bill form | H43: Discount type defaults to "No discount"; discount amount field is hidden; discount excluded from API payload | I43: Not Tested | J43: Functional | K43: Web | L43: Project docs | M43: EMI-183 | N43: Yes | O43: BillManagement/functional/CreateBillFlow.spec.ts | P43: B2B
A44: EMI-B2B-8217 | B44: Manual Test Cases — B2B Transactions | C44: CB-06 | D44: Detailed bill entry — add multiple items | E44: High | G44: Open Detailed Bill Entry, add ≥2 items with Name/Qty/Unit Price/Discount/VAT | H44: Bill Items list reflects all items; Section 3 confirmation shows per-item and aggregate totals | I44: Not Tested | J44: Functional | K44: Web | L44: Project docs | M44: EMI-183 | N44: Yes | O44: BillManagement/functional/CreateBillFlow.spec.ts | P44: B2B
...

Sheet Technical Updates
A1: TC ID | B1: Sub-Area | C1: Source ID | D1: Title | E1: Priority | F1: Preconditions | G1: Steps | H1: Expected Result | I1: Status | J1: Test Type | K1: Interface | L1: Source | M1: Jira Ref | N1: Automated | O1: Automated By | P1: Channel
A2: EMI-B2B-6750 | B2: 5.1.0 | C2: EMI-TC-5033 | D2: Checking the VAT checkbox applies VAT to the bill total | E2: Critical | F2: Edit bill form is open. VAT checkbox is unchecked. | G2: Check the VAT checkbox and observe the bill total. | H2: Bill total updates to include the applicable VAT amount. VAT line is shown in the bill summary. Change is reflected immediately without a page reload. | I2: Not Tested | J2: Functional | K2: Web | L2: AIO (Jira) | N2: No | P2: B2B
A3: EMI-B2B-6755 | B3: 5.1.0 | C3: EMI-TC-5038 | D3: Issue Date field is removed from the edit bill form | E3: Critical | F3: Edit bill form is open. | G3: Inspect the edit bill form for the Issue Date field. | H3: Issue Date field is not present in the form. It is fully removed, not disabled. No greyed-out or read-only date input remains. | I3: Not Tested | J3: Functional | K3: Web | L3: AIO (Jira) | M3: EMI-5199 | N3: No | P3: B2B
A4: EMI-B2B-6758 | B4: 5.1.0 | C4: EMI-TC-5041 | D4: VAT checkbox and field removals are applied in the single bill edit view | E4: Critical | F4: A single bill is open in edit mode. | G4: Inspect the single bill edit form for VAT field type and presence of Select Beneficiary and Issue Date. | H4: VAT is a checkbox. Select Beneficiary and Issue Date are absent. All other editable fields are present and functional. | I4: Not Tested | J4: Functional | K4: Web | L4: AIO (Jira) | M4: EMI-5199 | N4: No | P4: B2B
A5: EMI-B2B-6761 | B5: 5.1.0 | C5: EMI-TC-5044 | D5: VAT checkbox and field removals are applied in the detailed bill edit view | E5: Critical | F5: A detailed (multi-line) bill is open in edit mode. | G5: Inspect the detailed bill edit form for VAT field type and presence of Select Beneficiary and Issue Date. | H5: VAT is a checkbox. Select Beneficiary and Issue Date are absent. All line-item editable fields are present and functional. | I5: Not Tested | J5: Functional | K5: Web | L5: AIO (Jira) | M5: EMI-5199 | N5: No | P5: B2B
A6: EMI-B2B-6709 | B6: 5.1.0 | C6: EMI-TC-4640 | D6: SessionManager initialises correctly as a singleton via Koin | E6: High | F6: App is launched. Koin dependency modules are configured with SessionManager provided as singleton. | G6: 1. Launch the application 2. Resolve SessionManager from Koin in two separate places 3. Compare both instances | H6: Both resolved instances are the same object reference (singleton). SessionManager is not recreated on each resolution. | I6: Not Tested | J6: Functional | K6: Web | L6: AIO (Jira) | M6: EMI-5213 | N6: No | P6: B2B
A7: EMI-B2B-6710 | B7: 5.1.0 | C7: EMI-TC-4641 | D7: SessionManager starts session timeout coroutine on user login | E7: High | F7: User is on the login screen. SessionManager is initialised. | G7: 1. Complete user login successfully 2. Observe SessionManager coroutine state | H7: Session timeout coroutine is launched and running after login. Coroutine is scoped correctly and does not run before login. | I7: Not Tested | J7: Functional | K7: Web | L7: AIO (Jira) | M7: EMI-5213 | N7: No | P7: B2B
A8: EMI-B2B-6720 | B8: 5.1.0 | C8: EMI-TC-4651 | D8: Session handling in MainActivity behaves equivalently to former BaseActivity | E8: High | F8: Previous session behaviour documented. App is running with new architecture. | G8: 1. Perform a full user session: login, idle, timeout, re-login 2. Compare behaviour to pre-refactor baseline | H8: Session timeout, logout, and re-authentication behave identically to before. No regression in session lifecycle behaviour. | I8: Not Tested | J8: Functional | K8: Web | L8: AIO (Jira) | M8: EMI-5213 | N8: No | P8: B2B
A9: EMI-B2B-6721 | B9: 5.1.0 | C9: EMI-TC-4652 | D9: SessionTimeOutService is removed and no longer invoked | E9: High | F9: Refactor is complete. | G9: 1. Verify SessionTimeOutService does not exist in the codebase 2. Trigger session timeout scenario 3. Observe how timeout is handled | H9: SessionTimeOutService is absent. Timeout is handled entirely by SessionManager coroutine. No service binding or service lifecycle calls occur. | I9: Not Tested | J9: Functional | K9: Web | L9: AIO (Jira) | M9: EMI-5213 | N9: No | P9: B2B
A10: EMI-B2B-6722 | B10: 5.1.0 | C10: EMI-TC-4653 | D10: IdleTimerReceiver is removed and no broadcast intents are used for idle tracking | E10: High | F10: Refactor is complete. | G10: 1. Verify IdleTimerReceiver does not exist 2. Monitor system broadcast intents during app use 3. Trigger idle timeout | H10: IdleTimerReceiver is absent. No broadcast intents sent or received for idle timer. Idle tracking handled entirely within SessionManager. | I10: Not Tested | J10: Functional | K10: Web | L10: AIO (Jira) | M10: EMI-5213 | N10: No | P10: B2B
A11: EMI-B2B-6727 | B11: 5.1.0 | C11: EMI-TC-4658 | D11: SessionManager is provided as singleton in Koin modules | E11: High | F11: App is launched with updated Koin configuration. | G11: 1. Resolve SessionManager from Koin in MainActivity 2. Resolve SessionManager from Koin in another component 3. Compare instances | H11: Both resolutions return the same singleton instance. Koin module declares SessionManager with single() scope. | I11: Not Tested | J11: Functional | K11: Web | L11: AIO (Jira) | M11: EMI-5213 | N11: No | P11: B2B
A12: EMI-B2B-6728 | B12: 5.1.0 | C12: EMI-TC-4659 | D12: AppCoreModule caches environment settings — not re-read on every access | E12: High | F12: App is running. AppCoreModule is initialised. | G12: 1. Access environment settings multiple times via AppCoreModule 2. Monitor how often settings are read from source (file/prefs/network) | H12: Environment settings are read once and cached. Subsequent accesses return the cached value without re-reading the source. | I12: Not Tested | J12: Functional | K12: Web | L12: AIO (Jira) | M12: EMI-5213 | N12: No | P12: B2B
A13: EMI-B2B-6732 | B13: 5.1.0 | C13: EMI-TC-4663 | D13: Full session lifecycle: login, background app, foreground before timeout | E13: High | F13: User is logged in. | G13: 1. Log in 2. Background the app 3. Return to foreground before timeout elapses 4. Observe session state | H13: Session remains active on foreground return. Idle timer is handled correctly across background/foreground transitions. No unintended logout. | I13: Not Tested | J13: Functional | K13: Web | L13: AIO (Jira) | M13: EMI-5213 | N13: No | P13: B2B
A14: EMI-B2B-6751 | B14: 5.1.0 | C14: EMI-TC-5034 | D14: Unchecking the VAT checkbox removes VAT from the bill total | E14: High | F14: Edit bill form is open. VAT checkbox is currently checked. | G14: Uncheck the VAT checkbox. | H14: VAT is removed from the bill total. Total recalculates immediately. VAT line disappears from the bill summary. | I14: Not Tested | J14: Functional | K14: Web | L14: AIO (Jira) | N14: No | P14: B2B
A15: EMI-B2B-6752 | B15: 5.1.0 | C15: EMI-TC-5035 | D15: VAT checkbox state is saved correctly on form submission | E15: High | F15: Edit bill form is open. VAT checkbox toggled to a new state. | G15: Submit the edit bill form. | H15: Saved bill reflects the new VAT checkbox state. Re-opening the bill shows the checkbox in the saved position. Total matches the expected amount with or without VAT. | I15: Not Tested | J15: Functional | K15: Web | L15: AIO (Jira) | N15: No | P15: B2B
A16: EMI-B2B-6753 | B16: 5.1.0 | C16: EMI-TC-5036 | D16: Old VAT input or dropdown is no longer present in the edit form | E16: High | F16: Edit bill form is open after the update has been deployed. | G16: Inspect the form for any text input, number field, or dropdown previously used for VAT entry. | H16: No VAT text input or dropdown exists. Only the checkbox is present. No legacy VAT field remains in the DOM. | I16: Not Tested | J16: Functional | K16: Web | L16: AIO (Jira) | N16: No | P16: B2B
A17: EMI-B2B-6756 | B17: 5.1.0 | C17: EMI-TC-5039 | D17: Removing uneditable fields does not affect other editable fields | E17: High | F17: Edit bill form is open after removal of uneditable fields. | G17: Inspect and interact with the remaining editable fields (e.g. amount, description, VAT checkbox). | H17: All remaining editable fields are functional and properly laid out. No field shifts, overlaps, or broken spacing caused by the removal. | I17: Not Tested | J17: Functional | K17: Web | L17: AIO (Jira) | M17: EMI-5199 | N17: No | P17: B2B
A18: EMI-B2B-6763 | B18: 5.1.0 | C18: EMI-TC-5046 | D18: VAT checkbox state applies consistently across all line items in detailed view | E18: High | F18: Detailed bill with multiple line items is in edit mode. VAT checkbox is at the bill level. | G18: Toggle the VAT checkbox and inspect all line-item totals. | H18: VAT is applied or removed consistently across all line items. No line item retains a conflicting VAT state. Grand total recalculates correctly. | I18: Not Tested | J18: Functional | K18: Web | L18: AIO (Jira) | M18: EMI-5199 | N18: No | P18: B2B
A19: EMI-B2B-6730 | B19: 5.1.0 | C19: EMI-TC-4661 | D19: Unused constants are removed — no dead code references in modules | E19: Medium | F19: Refactor is complete. | G19: 1. Review Koin modules and AppCoreModule for any unused constants 2. Run static analysis / lint | H19: No unused constants in the updated modules. Lint passes without unused symbol warnings for removed items. | I19: Not Tested | J19: Functional | K19: Web | L19: AIO (Jira) | M19: EMI-5213 | N19: No | P19: B2B
A20: EMI-B2B-6759 | B20: 5.1.0 | C20: EMI-TC-5042 | D20: Single bill edit saves correctly with the new form structure | E20: Critical | F20: Single bill edit form open. User modifies amount and toggles VAT checkbox. | G20: Submit the form. | H20: Bill is saved successfully. Updated amount and VAT state are reflected when the bill is reopened. No error from missing removed fields. | I20: Not Tested | J20: Negative | K20: Web | L20: AIO (Jira) | M20: EMI-5199 | N20: No | P20: B2B
A21: EMI-B2B-6762 | B21: 5.1.0 | C21: EMI-TC-5045 | D21: Detailed bill edit saves correctly with the new form structure | E21: Critical | F21: Detailed bill edit form open. User modifies a line-item amount and checks the VAT checkbox. | G21: Submit the form. | H21: Bill is saved successfully. All changes persist on re-open. No error from missing removed fields. Line-item totals reflect the VAT state. | I21: Not Tested | J21: Negative | K21: Web | L21: AIO (Jira) | M21: EMI-5199 | N21: No | P21: B2B
A22: EMI-B2B-6713 | B22: 5.1.0 | C22: EMI-TC-4644 | D22: Reset flag mechanism prevents unnecessary coroutine restarts | E22: High | F22: User is actively using the app. Multiple rapid interactions occur. | G22: 1. Rapidly trigger multiple user interaction events 2. Observe coroutine job count and reset flag state | H22: Reset flag is set on first interaction and coroutine is restarted only once per idle cycle. No coroutine churn — multiple rapid events do not spawn multiple coroutine jobs. | I22: Not Tested | J22: Negative | K22: Web | L22: AIO (Jira) | M22: EMI-5213 | N22: No | P22: B2B
A23: EMI-B2B-6719 | B23: 5.1.0 | C23: EMI-TC-4650 | D23: BaseActivity is fully removed — no residual references exist | E23: High | F23: Refactor is complete. | G23: 1. Search codebase for any references to BaseActivity 2. Verify no classes extend BaseActivity | H23: BaseActivity does not exist. No classes extend or reference BaseActivity. Build succeeds without errors. | I23: Not Tested | J23: Negative | K23: Web | L23: AIO (Jira) | M23: EMI-5213 | N23: No | P23: B2B
A24: EMI-B2B-6735 | B24: 5.1.0 | C24: EMI-TC-4666 | D24: Multiple rapid session resets do not cause coroutine job accumulation | E24: High | F24: User is logged in. Rapid interactions occur. | G24: 1. Rapidly trigger 50+ user interaction events within a second 2. Monitor active coroutine job count | H24: Coroutine job count remains at 1 (the active timeout job). No job accumulation occurs. Reset flag mechanism prevents redundant restarts. | I24: Not Tested | J24: Negative | K24: Web | L24: AIO (Jira) | M24: EMI-5213 | N24: No | P24: B2B
A25: EMI-B2B-6729 | B25: 5.1.0 | C25: EMI-TC-4660 | D25: AppCoreModule cache is invalidated correctly when environment changes | E25: Medium | F25: App is running. Cached environment settings exist. | G25: 1. Change the environment configuration 2. Access environment settings via AppCoreModule | H25: Cache is refreshed after environment change. Stale cached values are not returned after a config update. | I25: Not Tested | J25: Negative | K25: Web | L25: AIO (Jira) | M25: EMI-5213 | N25: No | P25: B2B
A26: EMI-B2B-6754 | B26: 5.1.0 | C26: EMI-TC-5037 | D26: Select Beneficiary field is removed from the edit bill form | E26: Critical | F26: Edit bill form is open. | G26: Inspect the edit bill form for the Select Beneficiary field. | H26: The Select Beneficiary field is not present in the form. It is not disabled or read-only — it is completely absent. No empty placeholder remains. | I26: Not Tested | J26: Edge / Boundary | K26: Web | L26: AIO (Jira) | N26: No | P26: B2B
A27: EMI-B2B-6757 | B27: 5.1.0 | C27: EMI-TC-5040 | D27: Disabled fields are not sent in the form payload when submitting | E27: High | F27: Edit bill form submitted after removal of uneditable fields. | G27: Submit the form and inspect the API request payload. | H27: The payload does not include Select Beneficiary or Issue Date fields. No null or empty values for removed fields are sent to the backend. | I27: Not Tested | J27: Edge / Boundary | K27: Web | L27: AIO (Jira) | M27: EMI-5199 | N27: No | P27: B2B
A28: EMI-B2B-6736 | B28: 5.1.0 | C28: EMI-TC-4856 | D28: Annotated method executes when user holds the required privilege | E28: Critical | F28: Repository method annotated @RequiresPrivilege(ADMIN). User session carries ADMIN privilege. | G28: Call the annotated repository method. | H28: Method executes successfully. Guard intercepts, confirms privilege, and delegates to the real implementation. | I28: Not Tested | J28: Security | K28: Web | L28: AIO (Jira) | N28: No | P28: B2B
A29: EMI-B2B-6739 | B29: 5.1.0 | C29: EMI-TC-4859 | D29: Guard blocks call and throws when required privilege is missing | E29: Critical | F29: Repository method requires WRITE. Current user has READ only. | G29: Call the WRITE-guarded method as a READ-only user. | H29: Guard throws an access-denied exception before the real method body is entered. No data is read or written. | I29: Not Tested | J29: Security | K29: Web | L29: AIO (Jira) | M29: EMI-5208 | N29: No | P29: B2B
A30: EMI-B2B-6740 | B30: 5.1.0 | C30: EMI-TC-4860 | D30: Guard delegates call with original arguments when privilege passes | E30: Critical | F30: Repository method requires READ. User has READ. Method expects arguments (userId=42). | G30: Call the guarded method with userId=42. | H30: Real method is invoked with userId=42 unchanged. Return value is passed back to the caller unmodified. | I30: Not Tested | J30: Security | K30: Web | L30: AIO (Jira) | M30: EMI-5208 | N30: No | P30: B2B
A31: EMI-B2B-6741 | B31: 5.1.0 | C31: EMI-TC-4861 | D31: Privilege is evaluated at call time, not at proxy creation time | E31: Critical | F31: Proxy created while user has ADMIN. User privilege is downgraded to READ before the call. | G31: Call an ADMIN-required method after the privilege downgrade. | H31: Guard uses the current session context and throws access-denied. Construction-time privilege is not cached or reused. | I31: Not Tested | J31: Security | K31: Web | L31: AIO (Jira) | M31: EMI-5208 | N31: No | P31: B2B
A32: EMI-B2B-6744 | B32: 5.1.0 | C32: EMI-TC-4864 | D32: guardedSingleOf registers a singleton guarded proxy in Koin | E32: Critical | F32: Koin module uses guardedSingleOf(::UserRepositoryImpl) bind UserRepository::class. | G32: Resolve UserRepository from Koin twice. | H32: Both resolutions return the same instance. The resolved object is a PrivilegeGuard proxy, not the raw implementation. | I32: Not Tested | J32: Security | K32: Web | L32: AIO (Jira) | M32: EMI-5208 | N32: No | P32: B2B
A33: EMI-B2B-6714 | B33: 5.1.0 | C33: EMI-TC-4645 | D33: SessionManager cancels coroutine cleanly on user logout | E33: High | F33: User is logged in. Session timeout coroutine is active. | G33: 1. User manually logs out 2. Inspect coroutine state | H33: Session timeout coroutine is cancelled on logout. No timeout fires after logout. No memory leaks or dangling coroutine jobs. | I33: Not Tested | J33: Security | K33: Web | L33: AIO (Jira) | M33: EMI-5213 | N33: No | P33: B2B
A34: EMI-B2B-6715 | B34: 5.1.0 | C34: EMI-TC-4646 | D34: SessionManager handles token refresh before expiry | E34: High | F34: User is logged in. Access token is nearing expiry. | G34: 1. Allow token to approach expiry threshold 2. Observe SessionManager behaviour | H34: SessionManager initiates token refresh before expiry. User session continues uninterrupted. New token is stored and used for subsequent requests. | I34: Not Tested | J34: Security | K34: Web | L34: AIO (Jira) | M34: EMI-5213 | N34: No | P34: B2B
A35: EMI-B2B-6716 | B35: 5.1.0 | C35: EMI-TC-4647 | D35: SessionManager logs out user when token refresh fails | E35: High | F35: User is logged in. Access token is expired. Refresh attempt fails (e.g., network error or revoked token). | G35: 1. Allow token to expire 2. Simulate refresh failure 3. Observe app behaviour | H35: SessionManager detects refresh failure. User is redirected to login screen. Session is fully cleared. | I35: Not Tested | J35: Security | K35: Web | L35: AIO (Jira) | M35: EMI-5213 | N35: No | P35: B2B
A36: EMI-B2B-6717 | B36: 5.1.0 | C36: EMI-TC-4648 | D36: Token lifecycle is managed in MainActivity, not BaseActivity | E36: High | F36: Code review / instrumentation confirms BaseActivity has been removed. | G36: 1. Verify BaseActivity no longer exists in the codebase 2. Verify token handling logic is present in MainActivity 3. Run a session scenario end-to-end | H36: No BaseActivity class exists. Token refresh and session expiry handling operate correctly from MainActivity. No regressions in token behaviour. | I36: Not Tested | J36: Security | K36: Web | L36: AIO (Jira) | M36: EMI-5213 | N36: No | P36: B2B
A37: EMI-B2B-6718 | B37: 5.1.0 | C37: EMI-TC-4649 | D37: Token expiry during background state triggers correct session handling on resume | E37: High | F37: User puts app in background. Token expires while app is backgrounded. | G37: 1. Log in and background the app 2. Wait for token to expire 3. Bring app to foreground | H37: On resume, SessionManager detects expired token. User is redirected to login screen. No crash or undefined behaviour on resume. | I37: Not Tested | J37: Security | K37: Web | L37: AIO (Jira) | M37: EMI-5213 | N37: No | P37: B2B
A38: EMI-B2B-6737 | B38: 5.1.0 | C38: EMI-TC-4857 | D38: Unannotated method bypasses the guard with no privilege check | E38: High | F38: Same repository has a second method with no annotation. User has no privileges. | G38: Call the unannotated method. | H38: Method executes normally. No privilege check is performed and no exception is thrown. | I38: Not Tested | J38: Security | K38: Web | L38: AIO (Jira) | N38: No | P38: B2B
A39: EMI-B2B-6738 | B39: 5.1.0 | C39: EMI-TC-4858 | D39: Invalid privilege value on annotation fails at startup | E39: High | F39: A repository method is annotated with an undefined privilege constant. | G39: Start the application with @RequiresPrivilege(UNDEFINED) on a repository method. | H39: Application throws a configuration exception naming the invalid privilege. It does not start silently. | I39: Not Tested | J39: Security | K39: Web | L39: AIO (Jira) | N39: No | P39: B2B
A40: EMI-B2B-6743 | B40: 5.1.0 | C40: EMI-TC-4863 | D40: Guard correctly intercepts Kotlin suspend functions | E40: High | F40: Repository has a suspend fun annotated with @RequiresPrivilege. User lacks the privilege. | G40: Call the suspend function from a coroutine scope without the required privilege. | H40: Guard throws access-denied within the coroutine. Exception propagates to the coroutine's exception handler without context corruption. | I40: Not Tested | J40: Security | K40: Web | L40: AIO (Jira) | M40: EMI-5208 | N40: No | P40: B2B
...

Sheet Deep Payment
A1: TC ID | B1: Sub-Area | C1: Source ID | D1: Title | E1: Priority | F1: Preconditions | G1: Steps | H1: Expected Result | I1: Status | J1: Test Type | K1: Interface | L1: Source | M1: Jira Ref | N1: Automated | O1: Automated By | P1: Channel
A2: EMI-B2B-1043 | B2: Deep Payment | C2: EMI-TC-6637 | D2: Guest payment with OTP success | E2: Critical | F2: OTP required by risk rule for guest | G2: 1. Start guest payment. 2. Provide valid payer info. 3. Trigger OTP. 4. Enter correct OTP within allowed time. | H2: OTP is verified; otp_verified=true recorded. User continues to gateway. Flow same as D1 on success. | I2: Not Tested | J2: Functional | K2: Web | L2: AIO (Jira) | M2: EMI-5368 | N2: No | P2: B2B
A3: EMI-B2B-1052 | B3: Deep Payment | C3: EMI-TC-6646 | D3: Session expiry during payment | E3: Critical | F3: Logged-in user session times out mid-flow | G3: 1. Start wallet payment. 2. Let session expire before confirm. 3. Try to confirm payment. | H3: User is forced to re-authenticate. Payment not executed without valid session. No inconsistent attempts created. After login, user can retry. | I3: Not Tested | J3: Functional | K3: Web | L3: AIO (Jira) | M3: EMI-5368 | N3: No | P3: B2B
A4: EMI-B2B-1074 | B4: Deep Payment | C4: EMI-TC-6668 | D4: OTP requirement is skipped when risk config does not require it | E4: Critical | F4: A payable invoice/bill with an ACTIVE payment link exists. OTP is NOT required by the current risk configuration. | G4: 1. Open hosted payment page as a guest. 2. Enter valid payer info. 3. Observe whether OTP is requested. | H4: OTP step is not presented to the payer. Payment proceeds directly to gateway without OTP. No OTP record is created. payment_attempt.otp_verified reflects false/null per defined behavior. Flow is consistent with risk config setting. | I4: Not Tested | J4: Functional | K4: Web | L4: AIO (Jira) | M4: EMI-5368 | N4: No | P4: B2B
A5: EMI-B2B-1075 | B5: Deep Payment | C5: EMI-TC-6669 | D5: Partial payment via wallet — invoice remains open, link stays ACTIVE | E5: Critical | F5: An invoice/bill supports partial payment (per invoice/bill rules). A payment link exists. Logged-in payer pays less than the full outstanding amount. | G5: 1. Open hosted payment page as a logged-in user. 2. Choose 'Pay with Wallet'. 3. Submit a partial amount (less than full outstanding). 4. Verify payment is accepted. 5. Check invoice outstanding balance. 6. Check payment link status. | H5: Payment attempt is marked SUCCESS for the partial amount. Invoice outstanding balance is reduced by the paid amount (not closed). Invoice remains in partially-paid / open state per invoice/bill rules. payment_link status remains ACTIVE (not CONSUMED). Another payment can be initiated through the same link. | I5: Not Tested | J5: Functional | K5: Web | L5: AIO (Jira) | M5: EMI-5368 | N5: No | P5: B2B
